Traceback (most recent call last):
  File "/Users/jacobellena/opt/anaconda3/envs/dsi/lib/python3.7/site-packages/urllib3/contrib/pyopenssl.py", line 313, in recv_into
    return self.connection.recv_into(*args, **kwargs)
  File "/Users/jacobellena/opt/anaconda3/envs/dsi/lib/python3.7/site-packages/OpenSSL/SSL.py", line 1840, in recv_into
    self._raise_ssl_error(self._ssl, result)
  File "/Users/jacobellena/opt/anaconda3/envs/dsi/lib/python3.7/site-packages/OpenSSL/SSL.py", line 1663, in _raise_ssl_error
    raise SysCallError(errno, errorcode.get(errno))
OpenSSL.SSL.SysCallError: (54, 'ECONNRESET')

During handling of the above exception, another exception occurred:

Traceback (most recent call last):
  File "/Users/jacobellena/opt/anaconda3/envs/dsi/lib/python3.7/site-packages/urllib3/response.py", line 425, in _error_catcher
    yield
  File "/Users/jacobellena/opt/anaconda3/envs/dsi/lib/python3.7/site-packages/urllib3/response.py", line 507, in read
    data = self._fp.read(amt) if not fp_closed else b""
  File "/Users/jacobellena/opt/anaconda3/envs/dsi/lib/python3.7/http/client.py", line 457, in read
    n = self.readinto(b)
  File "/Users/jacobellena/opt/anaconda3/envs/dsi/lib/python3.7/http/client.py", line 501, in readinto
    n = self.fp.readinto(b)
  File "/Users/jacobellena/opt/anaconda3/envs/dsi/lib/python3.7/socket.py", line 589, in readinto
    return self._sock.recv_into(b)
  File "/Users/jacobellena/opt/anaconda3/envs/dsi/lib/python3.7/site-packages/urllib3/contrib/pyopenssl.py", line 318, in recv_into
    raise SocketError(str(e))
OSError: (54, 'ECONNRESET')

During handling of the above exception, another exception occurred:

Traceback (most recent call last):
  File "/Users/jacobellena/opt/anaconda3/envs/dsi/lib/python3.7/site-packages/requests/models.py", line 750, in generate
    for chunk in self.raw.stream(chunk_size, decode_content=True):
  File "/Users/jacobellena/opt/anaconda3/envs/dsi/lib/python3.7/site-packages/urllib3/response.py", line 564, in stream
    data = self.read(amt=amt, decode_content=decode_content)
  File "/Users/jacobellena/opt/anaconda3/envs/dsi/lib/python3.7/site-packages/urllib3/response.py", line 529, in read
    raise IncompleteRead(self._fp_bytes_read, self.length_remaining)
  File "/Users/jacobellena/opt/anaconda3/envs/dsi/lib/python3.7/contextlib.py", line 130, in __exit__
    self.gen.throw(type, value, traceback)
  File "/Users/jacobellena/opt/anaconda3/envs/dsi/lib/python3.7/site-packages/urllib3/response.py", line 443, in _error_catcher
    raise ProtocolError("Connection broken: %r" % e, e)
urllib3.exceptions.ProtocolError: ('Connection broken: OSError("(54, \'ECONNRESET\')")', OSError("(54, 'ECONNRESET')"))

During handling of the above exception, another exception occurred:

Traceback (most recent call last):
  File "/Users/jacobellena/Downloads/image-file-list.py", line 63, in <module>
    image_grab(image, flight, event_number)
  File "/Users/jacobellena/Downloads/image-file-list.py", line 47, in image_grab
    image_grab = requests.get(image_url)
  File "/Users/jacobellena/opt/anaconda3/envs/dsi/lib/python3.7/site-packages/requests/api.py", line 75, in get
    return request('get', url, params=params, **kwargs)
  File "/Users/jacobellena/opt/anaconda3/envs/dsi/lib/python3.7/site-packages/requests/api.py", line 60, in request
    return session.request(method=method, url=url, **kwargs)
  File "/Users/jacobellena/opt/anaconda3/envs/dsi/lib/python3.7/site-packages/requests/sessions.py", line 533, in request
    resp = self.send(prep, **send_kwargs)
  File "/Users/jacobellena/opt/anaconda3/envs/dsi/lib/python3.7/site-packages/requests/sessions.py", line 686, in send
    r.content
  File "/Users/jacobellena/opt/anaconda3/envs/dsi/lib/python3.7/site-packages/requests/models.py", line 828, in content
    self._content = b''.join(self.iter_content(CONTENT_CHUNK_SIZE)) or b''
  File "/Users/jacobellena/opt/anaconda3/envs/dsi/lib/python3.7/site-packages/requests/models.py", line 753, in generate
    raise ChunkedEncodingError(e)
requests.exceptions.ChunkedEncodingError: ('Connection broken: OSError("(54, \'ECONNRESET\')")', OSError("(54, 'ECONNRESET')"))
(dsi) 
